Workbook

Sheet Source_Data
A1: EPS 1995 Arrears - Source Data
A3: Year | B3: Taxable Income before Arrears | C3: Arrears | D3: Taxable Income after Arrears | E3: Tax Regime | F3: Category | H3: Workbook note | I3: Edit this sheet only if source arrears/income data changes.
A4: 2014-15 | B4: 0 | C4: 0 | D4: =B4+C4 -> 0 | E4: OLD | F4: Resident-Normal Citizen | H4: Receipt year | I4: 2025-26
A5: 2015-16 | B5: 0 | C5: 0 | D5: =B5+C5 -> 0 | E5: OLD | F5: Resident-Normal Citizen | H5: Assessment year | I5: 2026-27
A6: 2016-17 | B6: 0 | C6: 0 | D6: =B6+C6 -> 0 | E6: OLD | F6: Resident-Senior Citizen | H6: Relief basis | I6: Section 89(1), Rule 21A, Form 10E Annexure I
A7: 2017-18 | B7: 0 | C7: 0 | D7: =B7+C7 -> 0 | E7: OLD | F7: Resident-Senior Citizen | H7: Receipt-year arrears check | I7: =SUM(C4:C14) -> 0
A8: 2018-19 | B8: 0 | C8: 0 | D8: =B8+C8 -> 0 | E8: OLD | F8: Resident-Normal Citizen | H8: Status | I8: =IF(I7=C15,"OK","Check receipt-year arrears") -> OK
A9: 2019-20 | B9: 0 | C9: 0 | D9: =B9+C9 -> 0 | E9: OLD | F9: Resident-Normal Citizen
A10: 2020-21 | B10: 0 | C10: 0 | D10: =B10+C10 -> 0 | E10: OLD | F10: Resident-Senior Citizen | H10: Form 10E details
A11: 2021-22 | B11: 0 | C11: 0 | D11: =B11+C11 -> 0 | E11: OLD | F11: Resident-Senior Citizen | H11: Name
A12: 2022-23 | B12: 0 | C12: 0 | D12: =B12+C12 -> 0 | E12: NEW | F12: Resident-Senior Citizen | H12: PAN
A13: 2023-24 | B13: 0 | C13: 0 | D13: =B13+C13 -> 0 | E13: NEW | F13: Resident-Senior Citizen | H13: Address
A14: 2024-25 | B14: 0 | C14: 0 | D14: =B14+C14 -> 0 | E14: NEW | F14: Resident-Senior Citizen | H14: Status | I14: RESIDENT - SR CITIZEN
A15: 2025-26 | B15: 0 | C15: =SUM(C4:C14) -> 0 | D15: =B15+C15 -> 0 | E15: NEW | F15: Resident-Senior Citizen
A17: Note : Taxable Income before Arrears excludes capital gains/special-rate income where normal slabs do not apply.

Sheet Relief_Calculation
A1: Section 89(1) Relief Calculation
A3: Financial Year | B3: Taxable income before arrears | C3: Arrears attributable | D3: Taxable income after arrears | E3: Regime | F3: Category | G3: Basic tax before | H3: Rebate before | I3: Surcharge before | J3: Cess before | K3: Tax before | L3: Basic tax after | M3: Rebate after | N3: Surcharge after | O3: Cess after | P3: Tax after | Q3: Extra tax due to arrears
A4: =Source_Data!A4 -> 2014-15 | B4: =Source_Data!B4 -> 0 | C4: =Source_Data!C4 -> 0 | D4: =Source_Data!D4 -> 0 | E4: =Source_Data!E4 -> OLD | F4: =Source_Data!F4 -> Resident-Normal Citizen | G4: =Tax_Engine!G4 -> 0 | H4: =Tax_Engine!H4 -> 0 | I4: =Tax_Engine!I4 -> 0 | J4: =Tax_Engine!J4 -> 0 | K4: =ROUND(G4-H4+I4+J4,2) -> 0 | L4: =Tax_Engine!L4 -> 0 | M4: =Tax_Engine!M4 -> 0 | N4: =Tax_Engine!N4 -> 0 | O4: =Tax_Engine!O4 -> 0 | P4: =ROUND(L4-M4+N4+O4,2) -> 0 | Q4: =ROUND(P4-K4,2) -> 0
A5: =Source_Data!A5 -> 2015-16 | B5: =Source_Data!B5 -> 0 | C5: =Source_Data!C5 -> 0 | D5: =Source_Data!D5 -> 0 | E5: =Source_Data!E5 -> OLD | F5: =Source_Data!F5 -> Resident-Normal Citizen | G5: =Tax_Engine!G5 -> 0 | H5: =Tax_Engine!H5 -> 0 | I5: =Tax_Engine!I5 -> 0 | J5: =Tax_Engine!J5 -> 0 | K5: =ROUND(G5-H5+I5+J5,2) -> 0 | L5: =Tax_Engine!L5 -> 0 | M5: =Tax_Engine!M5 -> 0 | N5: =Tax_Engine!N5 -> 0 | O5: =Tax_Engine!O5 -> 0 | P5: =ROUND(L5-M5+N5+O5,2) -> 0 | Q5: =ROUND(P5-K5,2) -> 0
A6: =Source_Data!A6 -> 2016-17 | B6: =Source_Data!B6 -> 0 | C6: =Source_Data!C6 -> 0 | D6: =Source_Data!D6 -> 0 | E6: =Source_Data!E6 -> OLD | F6: =Source_Data!F6 -> Resident-Senior Citizen | G6: =Tax_Engine!G6 -> 0 | H6: =Tax_Engine!H6 -> 0 | I6: =Tax_Engine!I6 -> 0 | J6: =Tax_Engine!J6 -> 0 | K6: =ROUND(G6-H6+I6+J6,2) -> 0 | L6: =Tax_Engine!L6 -> 0 | M6: =Tax_Engine!M6 -> 0 | N6: =Tax_Engine!N6 -> 0 | O6: =Tax_Engine!O6 -> 0 | P6: =ROUND(L6-M6+N6+O6,2) -> 0 | Q6: =ROUND(P6-K6,2) -> 0
A7: =Source_Data!A7 -> 2017-18 | B7: =Source_Data!B7 -> 0 | C7: =Source_Data!C7 -> 0 | D7: =Source_Data!D7 -> 0 | E7: =Source_Data!E7 -> OLD | F7: =Source_Data!F7 -> Resident-Senior Citizen | G7: =Tax_Engine!G7 -> 0 | H7: =Tax_Engine!H7 -> 0 | I7: =Tax_Engine!I7 -> 0 | J7: =Tax_Engine!J7 -> 0 | K7: =ROUND(G7-H7+I7+J7,2) -> 0 | L7: =Tax_Engine!L7 -> 0 | M7: =Tax_Engine!M7 -> 0 | N7: =Tax_Engine!N7 -> 0 | O7: =Tax_Engine!O7 -> 0 | P7: =ROUND(L7-M7+N7+O7,2) -> 0 | Q7: =ROUND(P7-K7,2) -> 0
A8: =Source_Data!A8 -> 2018-19 | B8: =Source_Data!B8 -> 0 | C8: =Source_Data!C8 -> 0 | D8: =Source_Data!D8 -> 0 | E8: =Source_Data!E8 -> OLD | F8: =Source_Data!F8 -> Resident-Normal Citizen | G8: =Tax_Engine!G8 -> 0 | H8: =Tax_Engine!H8 -> 0 | I8: =Tax_Engine!I8 -> 0 | J8: =Tax_Engine!J8 -> 0 | K8: =ROUND(G8-H8+I8+J8,2) -> 0 | L8: =Tax_Engine!L8 -> 0 | M8: =Tax_Engine!M8 -> 0 | N8: =Tax_Engine!N8 -> 0 | O8: =Tax_Engine!O8 -> 0 | P8: =ROUND(L8-M8+N8+O8,2) -> 0 | Q8: =ROUND(P8-K8,2) -> 0
A9: =Source_Data!A9 -> 2019-20 | B9: =Source_Data!B9 -> 0 | C9: =Source_Data!C9 -> 0 | D9: =Source_Data!D9 -> 0 | E9: =Source_Data!E9 -> OLD | F9: =Source_Data!F9 -> Resident-Normal Citizen | G9: =Tax_Engine!G9 -> 0 | H9: =Tax_Engine!H9 -> 0 | I9: =Tax_Engine!I9 -> 0 | J9: =Tax_Engine!J9 -> 0 | K9: =ROUND(G9-H9+I9+J9,2) -> 0 | L9: =Tax_Engine!L9 -> 0 | M9: =Tax_Engine!M9 -> 0 | N9: =Tax_Engine!N9 -> 0 | O9: =Tax_Engine!O9 -> 0 | P9: =ROUND(L9-M9+N9+O9,2) -> 0 | Q9: =ROUND(P9-K9,2) -> 0
A10: =Source_Data!A10 -> 2020-21 | B10: =Source_Data!B10 -> 0 | C10: =Source_Data!C10 -> 0 | D10: =Source_Data!D10 -> 0 | E10: =Source_Data!E10 -> OLD | F10: =Source_Data!F10 -> Resident-Senior Citizen | G10: =Tax_Engine!G10 -> 0 | H10: =Tax_Engine!H10 -> 0 | I10: =Tax_Engine!I10 -> 0 | J10: =Tax_Engine!J10 -> 0 | K10: =ROUND(G10-H10+I10+J10,2) -> 0 | L10: =Tax_Engine!L10 -> 0 | M10: =Tax_Engine!M10 -> 0 | N10: =Tax_Engine!N10 -> 0 | O10: =Tax_Engine!O10 -> 0 | P10: =ROUND(L10-M10+N10+O10,2) -> 0 | Q10: =ROUND(P10-K10,2) -> 0
A11: =Source_Data!A11 -> 2021-22 | B11: =Source_Data!B11 -> 0 | C11: =Source_Data!C11 -> 0 | D11: =Source_Data!D11 -> 0 | E11: =Source_Data!E11 -> OLD | F11: =Source_Data!F11 -> Resident-Senior Citizen | G11: =Tax_Engine!G11 -> 0 | H11: =Tax_Engine!H11 -> 0 | I11: =Tax_Engine!I11 -> 0 | J11: =Tax_Engine!J11 -> 0 | K11: =ROUND(G11-H11+I11+J11,2) -> 0 | L11: =Tax_Engine!L11 -> 0 | M11: =Tax_Engine!M11 -> 0 | N11: =Tax_Engine!N11 -> 0 | O11: =Tax_Engine!O11 -> 0 | P11: =ROUND(L11-M11+N11+O11,2) -> 0 | Q11: =ROUND(P11-K11,2) -> 0
A12: =Source_Data!A12 -> 2022-23 | B12: =Source_Data!B12 -> 0 | C12: =Source_Data!C12 -> 0 | D12: =Source_Data!D12 -> 0 | E12: =Source_Data!E12 -> NEW | F12: =Source_Data!F12 -> Resident-Senior Citizen | G12: =Tax_Engine!G12 -> 0 | H12: =Tax_Engine!H12 -> 0 | I12: =Tax_Engine!I12 -> 0 | J12: =Tax_Engine!J12 -> 0 | K12: =ROUND(G12-H12+I12+J12,2) -> 0 | L12: =Tax_Engine!L12 -> 0 | M12: =Tax_Engine!M12 -> 0 | N12: =Tax_Engine!N12 -> 0 | O12: =Tax_Engine!O12 -> 0 | P12: =ROUND(L12-M12+N12+O12,2) -> 0 | Q12: =ROUND(P12-K12,2) -> 0
A13: =Source_Data!A13 -> 2023-24 | B13: =Source_Data!B13 -> 0 | C13: =Source_Data!C13 -> 0 | D13: =Source_Data!D13 -> 0 | E13: =Source_Data!E13 -> NEW | F13: =Source_Data!F13 -> Resident-Senior Citizen | G13: =Tax_Engine!G13 -> 0 | H13: =Tax_Engine!H13 -> 0 | I13: =Tax_Engine!I13 -> 0 | J13: =Tax_Engine!J13 -> 0 | K13: =ROUND(G13-H13+I13+J13,2) -> 0 | L13: =Tax_Engine!L13 -> 0 | M13: =Tax_Engine!M13 -> 0 | N13: =Tax_Engine!N13 -> 0 | O13: =Tax_Engine!O13 -> 0 | P13: =ROUND(L13-M13+N13+O13,2) -> 0 | Q13: =ROUND(P13-K13,2) -> 0
A14: =Source_Data!A14 -> 2024-25 | B14: =Source_Data!B14 -> 0 | C14: =Source_Data!C14 -> 0 | D14: =Source_Data!D14 -> 0 | E14: =Source_Data!E14 -> NEW | F14: =Source_Data!F14 -> Resident-Senior Citizen | G14: =Tax_Engine!G14 -> 0 | H14: =Tax_Engine!H14 -> 0 | I14: =Tax_Engine!I14 -> 0 | J14: =Tax_Engine!J14 -> 0 | K14: =ROUND(G14-H14+I14+J14,2) -> 0 | L14: =Tax_Engine!L14 -> 0 | M14: =Tax_Engine!M14 -> 0 | N14: =Tax_Engine!N14 -> 0 | O14: =Tax_Engine!O14 -> 0 | P14: =ROUND(L14-M14+N14+O14,2) -> 0 | Q14: =ROUND(P14-K14,2) -> 0
A15: =Source_Data!A15 -> 2025-26 | B15: =Source_Data!B15 -> 0 | C15: =Source_Data!C15 -> 0 | D15: =Source_Data!D15 -> 0 | E15: =Source_Data!E15 -> NEW | F15: =Source_Data!F15 -> Resident-Senior Citizen | G15: =Tax_Engine!G15 -> 0 | H15: =Tax_Engine!H15 -> 0 | I15: =Tax_Engine!I15 -> 0 | J15: =Tax_Engine!J15 -> 0 | K15: =ROUND(G15-H15+I15+J15,2) -> 0 | L15: =Tax_Engine!L15 -> 0 | M15: =Tax_Engine!M15 -> 0 | N15: =Tax_Engine!N15 -> 0 | O15: =Tax_Engine!O15 -> 0 | P15: =ROUND(L15-M15+N15+O15,2) -> 0 | Q15: =ROUND(P15-K15,2) -> 0
A19: Relief Summary :
A20: Receipt financial year | B20: =Source_Data!I4 -> 2025-26
A21: Assessment year | B21: =Source_Data!I5 -> 2026-27
A22: Additional tax in receipt year | B22: =Q15 -> 0
A23: Additional tax attributable to earlier years | B23: =SUM(Q4:Q14) -> 0
A24: Section 89(1) relief | B24: =MAX(0,B22-B23) -> 0
A25: Net tax after relief in receipt year | B25: =P15-B24 -> 0

Sheet Form_10E
A1: Form 10E - Linked Working for Section 89(1) Relief
A3: Name | B3: =Source_Data!I11 -> 0
A4: PAN | B4: =Source_Data!I12 -> 0
A5: Address | B5: =Source_Data!I13 -> 0
A6: Status | B6: =Source_Data!I14 -> RESIDENT - SR CITIZEN
A7: Previous year in which arrears received | B7: =Relief_Calculation!B20 -> 2025-26
A8: Assessment year | B8: =Relief_Calculation!B21 -> 2026-27
A9: Relief claimed u/s 89(1) | B9: =ROUND(Relief_Calculation!B24,0) -> 0
A12: Annexure I - Arrears or Advance Salary
A13: Financial Year | B13: Arrears | C13: Total income excluding arrears | D13: Total income including arrears | E13: Tax on excluding arrears | F13: Tax on including arrears | G13: Additional tax | H13: Regime
A14: =Relief_Calculation!A4 -> 2014-15 | B14: =Relief_Calculation!C4 -> 0 | C14: =Relief_Calculation!B4 -> 0 | D14: =Relief_Calculation!D4 -> 0 | E14: =Relief_Calculation!K4 -> 0 | F14: =Relief_Calculation!P4 -> 0 | G14: =Relief_Calculation!Q4 -> 0 | H14: OLD
A15: =Relief_Calculation!A5 -> 2015-16 | B15: =Relief_Calculation!C5 -> 0 | C15: =Relief_Calculation!B5 -> 0 | D15: =Relief_Calculation!D5 -> 0 | E15: =Relief_Calculation!K5 -> 0 | F15: =Relief_Calculation!P5 -> 0 | G15: =Relief_Calculation!Q5 -> 0 | H15: OLD
A16: =Relief_Calculation!A6 -> 2016-17 | B16: =Relief_Calculation!C6 -> 0 | C16: =Relief_Calculation!B6 -> 0 | D16: =Relief_Calculation!D6 -> 0 | E16: =Relief_Calculation!K6 -> 0 | F16: =Relief_Calculation!P6 -> 0 | G16: =Relief_Calculation!Q6 -> 0 | H16: OLD
A17: =Relief_Calculation!A7 -> 2017-18 | B17: =Relief_Calculation!C7 -> 0 | C17: =Relief_Calculation!B7 -> 0 | D17: =Relief_Calculation!D7 -> 0 | E17: =Relief_Calculation!K7 -> 0 | F17: =Relief_Calculation!P7 -> 0 | G17: =Relief_Calculation!Q7 -> 0 | H17: OLD
A18: =Relief_Calculation!A8 -> 2018-19 | B18: =Relief_Calculation!C8 -> 0 | C18: =Relief_Calculation!B8 -> 0 | D18: =Relief_Calculation!D8 -> 0 | E18: =Relief_Calculation!K8 -> 0 | F18: =Relief_Calculation!P8 -> 0 | G18: =Relief_Calculation!Q8 -> 0 | H18: OLD
A19: =Relief_Calculation!A9 -> 2019-20 | B19: =Relief_Calculation!C9 -> 0 | C19: =Relief_Calculation!B9 -> 0 | D19: =Relief_Calculation!D9 -> 0 | E19: =Relief_Calculation!K9 -> 0 | F19: =Relief_Calculation!P9 -> 0 | G19: =Relief_Calculation!Q9 -> 0 | H19: OLD
A20: =Relief_Calculation!A10 -> 2020-21 | B20: =Relief_Calculation!C10 -> 0 | C20: =Relief_Calculation!B10 -> 0 | D20: =Relief_Calculation!D10 -> 0 | E20: =Relief_Calculation!K10 -> 0 | F20: =Relief_Calculation!P10 -> 0 | G20: =Relief_Calculation!Q10 -> 0 | H20: =Relief_Calculation!E10 -> OLD
A21: =Relief_Calculation!A11 -> 2021-22 | B21: =Relief_Calculation!C11 -> 0 | C21: =Relief_Calculation!B11 -> 0 | D21: =Relief_Calculation!D11 -> 0 | E21: =Relief_Calculation!K11 -> 0 | F21: =Relief_Calculation!P11 -> 0 | G21: =Relief_Calculation!Q11 -> 0 | H21: =Relief_Calculation!E11 -> OLD
A22: =Relief_Calculation!A12 -> 2022-23 | B22: =Relief_Calculation!C12 -> 0 | C22: =Relief_Calculation!B12 -> 0 | D22: =Relief_Calculation!D12 -> 0 | E22: =Relief_Calculation!K12 -> 0 | F22: =Relief_Calculation!P12 -> 0 | G22: =Relief_Calculation!Q12 -> 0 | H22: =Relief_Calculation!E12 -> NEW
A23: =Relief_Calculation!A13 -> 2023-24 | B23: =Relief_Calculation!C13 -> 0 | C23: =Relief_Calculation!B13 -> 0 | D23: =Relief_Calculation!D13 -> 0 | E23: =Relief_Calculation!K13 -> 0 | F23: =Relief_Calculation!P13 -> 0 | G23: =Relief_Calculation!Q13 -> 0 | H23: =Relief_Calculation!E13 -> NEW
A24: =Relief_Calculation!A14 -> 2024-25 | B24: =Relief_Calculation!C14 -> 0 | C24: =Relief_Calculation!B14 -> 0 | D24: =Relief_Calculation!D14 -> 0 | E24: =Relief_Calculation!K14 -> 0 | F24: =Relief_Calculation!P14 -> 0 | G24: =Relief_Calculation!Q14 -> 0 | H24: =Relief_Calculation!E14 -> NEW
A25: =Relief_Calculation!A15 -> 2025-26 | B25: =Relief_Calculation!C15 -> 0 | C25: =Relief_Calculation!B15 -> 0 | D25: =Relief_Calculation!D15 -> 0 | E25: =Relief_Calculation!K15 -> 0 | F25: =Relief_Calculation!P15 -> 0 | G25: =Relief_Calculation!Q15 -> 0 | H25: =Relief_Calculation!E15 -> NEW
A28: Computation of relief claimed in Form 10E
A29: Tax on income including arrears in year of receipt | B29: =Relief_Calculation!P15 -> 0
A30: Tax on income excluding arrears in year of receipt | B30: =Relief_Calculation!K15 -> 0
A31: Extra tax payable in year of receipt | B31: =Relief_Calculation!B22 -> 0
A32: Aggregate extra tax for earlier years | B32: =Relief_Calculation!B23 -> 0
A33: Relief under section 89(1) | B33: =Relief_Calculation!B24 -> 0

Sheet Checks
A1: Workbook Checks
A3: Check | B3: Formula | C3: Expected / meaning | D3: Status
A4: Receipt-year arrears equals total earlier arrears | B4: =Source_Data!C15-SUM(Source_Data!C4:C14) -> 0 | C4: OK | D4: =IF(B4=0,"OK","Check") -> OK
A5: Taxable after = before + arrears for every row | B5: =SUMPRODUCT(--(Source_Data!D4:D15<>Source_Data!B4:B15+Source_Data!C4:C15)) -> 0 | C5: OK | D5: =IF(B5=0,"OK","Check") -> OK
A6: Form relief equals calculation relief | B6: =Form_10E!B33-Relief_Calculation!B24 -> 0 | C6: OK | D6: =IF(ABS(B6)<1,"OK","Check") -> OK
A7: Relief is not negative | B7: =Relief_Calculation!B24 -> 0 | C7: OK | D7: =IF(B7>=0,"OK","Check") -> OK
A8: Receipt year used | B8: =Source_Data!I4 -> 2025-26
A9: Assessment year used | B9: =Source_Data!I5 -> 2026-27
A10: Tax regime dropdown present on Source_Data | B10: 0 | C10: OK | D10: OK
A11: Category dropdown present on Source_Data | B11: 0 | C11: OK | D11: OK
A12: Comparison selected tax equals relief calculation | B12: =SUMPRODUCT(--(ROUND(Tax_Regime_Comparison!G4:G15,0)<>ROUND(Relief_Calculation!K4:K15,0)))+SUMPRODUCT(--(ROUND(Tax_Regime_Comparison!H4:H15,0)<>ROUND(Relief_Calculation!P4:P15,0))) -> 0 | C12: OK | D12: =IF(B12=0,"OK","Check") -> OK
A13: FY 2014-15 added | B13: 2014-15 | C13: OK | D13: OK
A14: FY 2015-16 added | B14: 2015-16 | C14: OK | D14: OK

Sheet Tax_Rate_Assumptions
A1: Tax Rate Assumptions
A2: Rates are prefilled for resident individuals based on common slab structures. Review before filing if any surcharge, marginal relief, rebate, or special-rate income rule applies.
A4: Financial Year | B4: Regime | C4: Status | D4: Lower limit | E4: Upper limit | F4: Rate | H4: Named ranges used by formulas
A5: 2016-17 | B5: OLD | C5: Resident-Normal Citizen | D5: 0 | E5: 250000 | F5: 0 | H5: Slabs | I5: $A$5:$F$95 | J5: Tax slab brackets
A6: 2016-17 | B6: OLD | C6: Resident-Normal Citizen | D6: 250000 | E6: 500000 | F6: 0.1 | H6: Rebates | I6: $A$99:$E$108 | J6: Section 87A rebate inputs
A7: 2016-17 | B7: OLD | C7: Resident-Normal Citizen | D7: 500000 | E7: 1000000 | F7: 0.2 | H7: Surcharge | I7: $A$112:$F$180 | J7: Surcharge rates
A8: 2016-17 | B8: OLD | C8: Resident-Normal Citizen | D8: 1000000 | E8: 999999999 | F8: 0.3 | H8: Cess | I8: $A$184:$B$193 | J8: Cess rates
A9: 2016-17 | B9: OLD | C9: Resident-Senior Citizen | D9: 0 | E9: 300000 | F9: 0 | H9: Surcharge floor | I9: 5000000 | J9: Used for marginal relief
A10: 2016-17 | B10: OLD | C10: Resident-Senior Citizen | D10: 300000 | E10: 500000 | F10: 0.1 | H10: Formula style | I10: Editable assumptions | J10: No tax figures are hardcoded in calculation sheets
A11: 2016-17 | B11: OLD | C11: Resident-Senior Citizen | D11: 500000 | E11: 1000000 | F11: 0.2 | H11: Status match | I11: All/status text | J11: Specific status overrides All where supplied
A12: 2016-17 | B12: OLD | C12: Resident-Senior Citizen | D12: 1000000 | E12: 999999999 | F12: 0.3
A13: 2017-18 | B13: OLD | C13: Resident-Normal Citizen | D13: 0 | E13: 250000 | F13: 0
A14: 2017-18 | B14: OLD | C14: Resident-Normal Citizen | D14: 250000 | E14: 500000 | F14: 0.05
A15: 2017-18 | B15: OLD | C15: Resident-Normal Citizen | D15: 500000 | E15: 1000000 | F15: 0.2
A16: 2017-18 | B16: OLD | C16: Resident-Normal Citizen | D16: 1000000 | E16: 999999999 | F16: 0.3
A17: 2017-18 | B17: OLD | C17: Resident-Senior Citizen | D17: 0 | E17: 300000 | F17: 0
A18: 2017-18 | B18: OLD | C18: Resident-Senior Citizen | D18: 300000 | E18: 500000 | F18: 0.05
A19: 2017-18 | B19: OLD | C19: Resident-Senior Citizen | D19: 500000 | E19: 1000000 | F19: 0.2
A20: 2017-18 | B20: OLD | C20: Resident-Senior Citizen | D20: 1000000 | E20: 999999999 | F20: 0.3
A21: 2018-19 | B21: OLD | C21: Resident-Normal Citizen | D21: 0 | E21: 250000 | F21: 0
A22: 2018-19 | B22: OLD | C22: Resident-Normal Citizen | D22: 250000 | E22: 500000 | F22: 0.05
A23: 2018-19 | B23: OLD | C23: Resident-Normal Citizen | D23: 500000 | E23: 1000000 | F23: 0.2
... A79: 2025-26 | B79: NEW | C79: All | D79: 2400000 | E79: 999999999 | F79: 0.3
A98: Financial Year | B98: Regime | C98: Status | D98: Rebate threshold | E98: Maximum rebate
A99: 2016-17 | B99: OLD | C99: All | D99: 500000 | E99: 5000
A100: 2017-18 | B100: OLD | C100: All | D100: 350000 | E100: 2500
A101: 2018-19 | B101: OLD | C101: All | D101: 350000 | E101: 2500
A102: 2019-20 | B102: OLD | C102: All | D102: 500000 | E102: 12500
A103: 2020-21 | B103: OLD | C103: All | D103: 500000 | E103: 12500
A104: 2021-22 | B104: OLD | C104: All | D104: 500000 | E104: 12500
A105: 2022-23 | B105: OLD | C105: All | D105: 500000 | E105: 12500
A106: 2023-24 | B106: NEW | C106: All | D106: 700000 | E106: 25000
A107: 2024-25 | B107: NEW | C107: All | D107: 700000 | E107: 25000
A108: 2025-26 | B108: NEW | C108: All | D108: 1200000 | E108: 60000
A111: Financial Year | B111: Regime | C111: Status | D111: Lower threshold | E111: Upper threshold | F111: Surcharge rate
A112: 2016-17 | B112: OLD | C112: All | D112: 10000000 | E112: 999999999 | F112: 0.15
A113: 2017-18 | B113: OLD | C113: All | D113: 5000000 | E113: 10000000 | F113: 0.1
A114: 2017-18 | B114: OLD | C114: All | D114: 10000000 | E114: 999999999 | F114: 0.15
A115: 2018-19 | B115: OLD | C115: All | D115: 5000000 | E115: 10000000 | F115: 0.1
A116: 2018-19 | B116: OLD | C116: All | D116: 10000000 | E116: 999999999 | F116: 0.15
...

Sheet Tax_Engine
A1: Tax Engine - Stepwise Old/New Regime Computation
A3: Source row | B3: Financial Year | C3: Regime | D3: Category | E3: Income before | F3: Income after | G3: Basic before | H3: Rebate before | I3: Surcharge before | J3: Cess before | K3: Tax before | L3: Basic after | M3: Rebate after | N3: Surcharge after | O3: Cess after | P3: Tax after | Q3: Extra tax
A4: =4 -> 4 | B4: =Source_Data!A4 -> 2014-15 | C4: =Source_Data!E4 -> OLD | D4: =Source_Data!F4 -> Resident-Normal Citizen | E4: =Source_Data!B4 -> 0 | F4: =Source_Data!D4 -> 0 | G4: =ROUND(IF(C4="OLD",MAX(0,MIN(E4,500000)-IF(D4="Resident-Senior Citizen",300000,250000))*IF(B4="2016-17",10%,10%)+MAX(0,MIN(E4,1000000)-500000)*20%+MAX(0,E4-1000000)*30%,IF(OR(B4="2020-21",B4="2021-22",B4="2022-23"),MAX(0,MIN(E4,500000)-250000)*5%+MAX(0,MIN(E4,750000)-500000)*10%+MAX(0,MIN(E4,1000000)-750000)*15%+MAX(0,MIN(E4,1250000)-1000000)*20%+MAX(0,MIN(E4,1500000)-1250000)*25%+MAX(0,E4-1500000)*30%,IF(B4="2023-24",MAX(0,MIN(E4,600000)-300000)*5%+MAX(0,MIN(E4,900000)-600000)*10%+MAX(0,MIN(E4,1200000)-900000)*15%+MAX(0,MIN(E4,1500000)-1200000)*20%+MAX(0,E4-1500000)*30%,IF(B4="2024-25",MAX(0,MIN(E4,700000)-300000)*5%+MAX(0,MIN(E4,1000000)-700000)*10%+MAX(0,MIN(E4,1200000)-1000000)*15%+MAX(0,MIN(E4,1500000)-1200000)*20%+MAX(0,E4-1500000)*30%,IF(B4="2025-26",MAX(0,MIN(E4,800000)-400000)*5%+MAX(0,MIN(E4,1200000)-800000)*10%+MAX(0,MIN(E4,1600000)-1200000)*15%+MAX(0,MIN(E4,2000000)-1600000)*20%+MAX(0,MIN(E4,2400000)-2000000)*25%+MAX(0,E4-2400000)*30%,0))))),2) -> 0 | H4: =ROUND(MAX(IF(C4="OLD",IF(E4<=IF(OR(B4="2014-15",B4="2015-16",B4="2016-17"),500000,IF(OR(B4="2017-18",B4="2018-19"),350000,500000)),MIN(G4,IF(OR(B4="2014-15",B4="2015-16"),2000,IF(B4="2016-17",5000,IF(OR(B4="2017-18",B4="2018-19"),2500,12500)))),0),IF(E4<=IF(OR(B4="2023-24",B4="2024-25"),700000,IF(B4="2025-26",1200000,500000)),MIN(G4,IF(OR(B4="2023-24",B4="2024-25"),25000,IF(B4="2025-26",60000,12500))),0)),IF(AND(C4="NEW",B4="2025-26",E4>1200000),MAX(0,G4-(E4-1200000)),0)),2) -> 0 | I4: =ROUND(IF(C4="OLD",IF(OR(B4="2014-15",B4="2016-17"),IF(E4<=10000000,0,MIN((G4-H4)*15%,MAX(0,(G4-H4)*0%+(E4-10000000)*(70%-30%*0%)))),IF(B4="2015-16",IF(E4<=10000000,0,MIN((G4-H4)*12%,MAX(0,(G4-H4)*0%+(E4-10000000)*(70%-30%*0%)))),IF(OR(B4="2017-18",B4="2018-19"),IF(E4<=5000000,0,IF(E4<=10000000,MIN((G4-H4)*10%,MAX(0,(G4-H4)*0%+(E4-5000000)*(70%-30%*0%))),MIN((G4-H4)*15%,MAX(0,(G4-H4)*10%+(E4-10000000)*(70%-30%*10%))))),IF(E4<=5000000,0,IF(E4<=10000000,MIN((G4-H4)*10%,MAX(0,(G4-H4)*0%+(E4-5000000)*(70%-30%*0%))),IF(E4<=20000000,MIN((G4-H4)*15%,MAX(0,(G4-H4)*10%+(E4-10000000)*(70%-30%*10%))),IF(E4<=50000000,MIN((G4-H4)*25%,MAX(0,(G4-H4)*15%+(E4-20000000)*(70%-30%*15%))),MIN((G4-H4)*37%,MAX(0,(G4-H4)*25%+(E4-50000000)*(70%-30%*25%)))))))))),IF(OR(B4="2023-24",B4="2024-25",B4="2025-26"),IF(E4<=5000000,0,IF(E4<=10000000,MIN((G4-H4)*10%,MAX(0,(G4-H4)*0%+(E4-5000000)*(70%-30%*0%))),IF(E4<=20000000,MIN((G4-H4)*15%,MAX(0,(G4-H4)*10%+(E4-10000000)*(70%-30%*10%))),MIN((G4-H4)*25%,MAX(0,(G4-H4)*15%+(E4-20000000)*(70%-30%*15%)))))),IF(E4<=5000000,0,IF(E4<=10000000,MIN((G4-H4)*10%,MAX(0,(G4-H4)*0%+(E4-5000000)*(70%-30%*0%))),IF(E4<=20000000,MIN((G4-H4)*15%,MAX(0,(G4-H4)*10%+(E4-10000000)*(70%-30%*10%))),IF(E4<=50000000,MIN((G4-H4)*25%,MAX(0,(G4-H4)*15%+(E4-20000000)*(70%-30%*15%))),MIN((G4-H4)*37%,MAX(0,(G4-H4)*25%+(E4-50000000)*(70%-30%*25%))))))))),2) -> 0 | J4: =ROUND((G4-H4+I4)*IF(OR(B4="2014-15",B4="2015-16",B4="2016-17",B4="2017-18"),3%,4%),2) -> 0 | K4: =ROUND(G4-H4+I4+J4,2) -> 0 | L4: =ROUND(IF(C4="OLD",MAX(0,MIN(F4,500000)-IF(D4="Resident-Senior Citizen",300000,250000))*IF(B4="2016-17",10%,10%)+MAX(0,MIN(F4,1000000)-500000)*20%+MAX(0,F4-1000000)*30%,IF(OR(B4="2020-21",B4="2021-22",B4="2022-23"),MAX(0,MIN(F4,500000)-250000)*5%+MAX(0,MIN(F4,750000)-500000)*10%+MAX(0,MIN(F4,1000000)-750000)*15%+MAX(0,MIN(F4,1250000)-1000000)*20%+MAX(0,MIN(F4,1500000)-1250000)*25%+MAX(0,F4-1500000)*30%,IF(B4="2023-24",MAX(0,MIN(F4,600000)-300000)*5%+MAX(0,MIN(F4,900000)-600000)*10%+MAX(0,MIN(F4,1200000)-900000)*15%+MAX(0,MIN(F4,1500000)-1200000)*20%+MAX(0,F4-1500000)*30%,IF(B4="2024-25",MAX(0,MIN(F4,700000)-300000)*5%+MAX(0,MIN(F4,1000000)-700000)*10%+MAX(0,MIN(F4,1200000)-1000000)*15%+MAX(0,MIN(F4,1500000)-1200000)*20%+MAX(0,F4-1500000)*30%,IF(B4="2025-26",MAX(0,MIN(F4,800000)-400000)*5%+MAX(0,MIN(F4,1200000)-800000)*10%+MAX(0,MIN(F4,1600000)-1200000)*15%+MAX(0,MIN(F4,2000000)-1600000)*20%+MAX(0,MIN(F4,2400000)-2000000)*25%+MAX(0,F4-2400000)*30%,0))))),2) -> 0 | M4: =ROUND(MAX(IF(C4="OLD",IF(F4<=IF(OR(B4="2014-15",B4="2015-16",B4="2016-17"),500000,IF(OR(B4="2017-18",B4="2018-19"),350000,500000)),MIN(L4,IF(OR(B4="2014-15",B4="2015-16"),2000,IF(B4="2016-17",5000,IF(OR(B4="2017-18",B4="2018-19"),2500,12500)))),0),IF(F4<=IF(OR(B4="2023-24",B4="2024-25"),700000,IF(B4="2025-26",1200000,500000)),MIN(L4,IF(OR(B4="2023-24",B4="2024-25"),25000,IF(B4="2025-26",60000,12500))),0)),IF(AND(C4="NEW",B4="2025-26",F4>1200000),MAX(0,L4-(F4-1200000)),0)),2) -> 0 | N4: =ROUND(IF(C4="OLD",IF(OR(B4="2014-15",B4="2016-17"),IF(F4<=10000000,0,MIN((L4-M4)*15%,MAX(0,(L4-M4)*0%+(F4-10000000)*(70%-30%*0%)))),IF(B4="2015-16",IF(F4<=10000000,0,MIN((L4-M4)*12%,MAX(0,(L4-M4)*0%+(F4-10000000)*(70%-30%*0%)))),IF(OR(B4="2017-18",B4="2018-19"),IF(F4<=5000000,0,IF(F4<=10000000,MIN((L4-M4)*10%,MAX(0,(L4-M4)*0%+(F4-5000000)*(70%-30%*0%))),MIN((L4-M4)*15%,MAX(0,(L4-M4)*10%+(F4-10000000)*(70%-30%*10%))))),IF(F4<=5000000,0,IF(F4<=10000000,MIN((L4-M4)*10%,MAX(0,(L4-M4)*0%+(F4-5000000)*(70%-30%*0%))),IF(F4<=20000000,MIN((L4-M4)*15%,MAX(0,(L4-M4)*10%+(F4-10000000)*(70%-30%*10%))),IF(F4<=50000000,MIN((L4-M4)*25%,MAX(0,(L4-M4)*15%+(F4-20000000)*(70%-30%*15%))),MIN((L4-M4)*37%,MAX(0,(L4-M4)*25%+(F4-50000000)*(70%-30%*25%)))))))))),IF(OR(B4="2023-24",B4="2024-25",B4="2025-26"),IF(F4<=5000000,0,IF(F4<=10000000,MIN((L4-M4)*10%,MAX(0,(L4-M4)*0%+(F4-5000000)*(70%-30%*0%))),IF(F4<=20000000,MIN((L4-M4)*15%,MAX(0,(L4-M4)*10%+(F4-10000000)*(70%-30%*10%))),MIN((L4-M4)*25%,MAX(0,(L4-M4)*15%+(F4-20000000)*(70%-30%*15%)))))),IF(F4<=5000000,0,IF(F4<=10000000,MIN((L4-M4)*10%,MAX(0,(L4-M4)*0%+(F4-5000000)*(70%-30%*0%))),IF(F4<=20000000,MIN((L4-M4)*15%,MAX(0,(L4-M4)*10%+(F4-10000000)*(70%-30%*10%))),IF(F4<=50000000,MIN((L4-M4)*25%,MAX(0,(L4-M4)*15%+(F4-20000000)*(70%-30%*15%))),MIN((L4-M4)*37%,MAX(0,(L4-M4)*25%+(F4-50000000)*(70%-30%*25%))))))))),2) -> 0 | O4: =ROUND((L4-M4+N4)*IF(OR(B4="2014-15",B4="2015-16",B4="2016-17",B4="2017-18"),3%,4%),2) -> 0 | P4: =ROUND(L4-M4+N4+O4,2) -> 0 | Q4: =ROUND(P4-K4,2) -> 0
A5: =5 -> 5 | B5: =Source_Data!A5 -> 2015-16 | C5: =Source_Data!E5 -> OLD | D5: =Source_Data!F5 -> Resident-Normal Citizen | E5: =Source_Data!B5 -> 0 | F5: =Source_Data!D5 -> 0 | G5: =ROUND(IF(C5="OLD",MAX(0,MIN(E5,500000)-IF(D5="Resident-Senior Citizen",300000,250000))*IF(B5="2016-17",10%,10%)+MAX(0,MIN(E5,1000000)-500000)*20%+MAX(0,E5-1000000)*30%,IF(OR(B5="2020-21",B5="2021-22",B5="2022-23"),MAX(0,MIN(E5,500000)-250000)*5%+MAX(0,MIN(E5,750000)-500000)*10%+MAX(0,MIN(E5,1000000)-750000)*15%+MAX(0,MIN(E5,1250000)-1000000)*20%+MAX(0,MIN(E5,1500000)-1250000)*25%+MAX(0,E5-1500000)*30%,IF(B5="2023-24",MAX(0,MIN(E5,600000)-300000)*5%+MAX(0,MIN(E5,900000)-600000)*10%+MAX(0,MIN(E5,1200000)-900000)*15%+MAX(0,MIN(E5,1500000)-1200000)*20%+MAX(0,E5-1500000)*30%,IF(B5="2024-25",MAX(0,MIN(E5,700000)-300000)*5%+MAX(0,MIN(E5,1000000)-700000)*10%+MAX(0,MIN(E5,1200000)-1000000)*15%+MAX(0,MIN(E5,1500000)-1200000)*20%+MAX(0,E5-1500000)*30%,IF(B5="2025-26",MAX(0,MIN(E5,800000)-400000)*5%+MAX(0,MIN(E5,1200000)-800000)*10%+MAX(0,MIN(E5,1600000)-1200000)*15%+MAX(0,MIN(E5,2000000)-1600000)*20%+MAX(0,MIN(E5,2400000)-2000000)*25%+MAX(0,E5-2400000)*30%,0))))),2) -> 0 | H5: =ROUND(MAX(IF(C5="OLD",IF(E5<=IF(OR(B5="2014-15",B5="2015-16",B5="2016-17"),500000,IF(OR(B5="2017-18",B5="2018-19"),350000,500000)),MIN(G5,IF(OR(B5="2014-15",B5="2015-16"),2000,IF(B5="2016-17",5000,IF(OR(B5="2017-18",B5="2018-19"),2500,12500)))),0),IF(E5<=IF(OR(B5="2023-24",B5="2024-25"),700000,IF(B5="2025-26",1200000,500000)),MIN(G5,IF(OR(B5="2023-24",B5="2024-25"),25000,IF(B5="2025-26",60000,12500))),0)),IF(AND(C5="NEW",B5="2025-26",E5>1200000),MAX(0,G5-(E5-1200000)),0)),2) -> 0 | I5: =ROUND(IF(C5="OLD",IF(OR(B5="2014-15",B5="2016-17"),IF(E5<=10000000,0,MIN((G5-H5)*15%,MAX(0,(G5-H5)*0%+(E5-10000000)*(70%-30%*0%)))),IF(B5="2015-16",IF(E5<=10000000,0,MIN((G5-H5)*12%,MAX(0,(G5-H5)*0%+(E5-10000000)*(70%-30%*0%)))),IF(OR(B5="2017-18",B5="2018-19"),IF(E5<=5000000,0,IF(E5<=10000000,MIN((G5-H5)*10%,MAX(0,(G5-H5)*0%+(E5-5000000)*(70%-30%*0%))),MIN((G5-H5)*15%,MAX(0,(G5-H5)*10%+(E5-10000000)*(70%-30%*10%))))),IF(E5<=5000000,0,IF(E5<=10000000,MIN((G5-H5)*10%,MAX(0,(G5-H5)*0%+(E5-5000000)*(70%-30%*0%))),IF(E5<=20000000,MIN((G5-H5)*15%,MAX(0,(G5-H5)*10%+(E5-10000000)*(70%-30%*10%))),IF(E5<=50000000,MIN((G5-H5)*25%,MAX(0,(G5-H5)*15%+(E5-20000000)*(70%-30%*15%))),MIN((G5-H5)*37%,MAX(0,(G5-H5)*25%+(E5-50000000)*(70%-30%*25%)))))))))),IF(OR(B5="2023-24",B5="2024-25",B5="2025-26"),IF(E5<=5000000,0,IF(E5<=10000000,MIN((G5-H5)*10%,MAX(0,(G5-H5)*0%+(E5-5000000)*(70%-30%*0%))),IF(E5<=20000000,MIN((G5-H5)*15%,MAX(0,(G5-H5)*10%+(E5-10000000)*(70%-30%*10%))),MIN((G5-H5)*25%,MAX(0,(G5-H5)*15%+(E5-20000000)*(70%-30%*15%)))))),IF(E5<=5000000,0,IF(E5<=10000000,MIN((G5-H5)*10%,MAX(0,(G5-H5)*0%+(E5-5000000)*(70%-30%*0%))),IF(E5<=20000000,MIN((G5-H5)*15%,MAX(0,(G5-H5)*10%+(E5-10000000)*(70%-30%*10%))),IF(E5<=50000000,MIN((G5-H5)*25%,MAX(0,(G5-H5)*15%+(E5-20000000)*(70%-30%*15%))),MIN((G5-H5)*37%,MAX(0,(G5-H5)*25%+(E5-50000000)*(70%-30%*25%))))))))),2) -> 0 | J5: =ROUND((G5-H5+I5)*IF(OR(B5="2014-15",B5="2015-16",B5="2016-17",B5="2017-18"),3%,4%),2) -> 0 | K5: =ROUND(G5-H5+I5+J5,2) -> 0 | L5: =ROUND(IF(C5="OLD",MAX(0,MIN(F5,500000)-IF(D5="Resident-Senior Citizen",300000,250000))*IF(B5="2016-17",10%,10%)+MAX(0,MIN(F5,1000000)-500000)*20%+MAX(0,F5-1000000)*30%,IF(OR(B5="2020-21",B5="2021-22",B5="2022-23"),MAX(0,MIN(F5,500000)-250000)*5%+MAX(0,MIN(F5,750000)-500000)*10%+MAX(0,MIN(F5,1000000)-750000)*15%+MAX(0,MIN(F5,1250000)-1000000)*20%+MAX(0,MIN(F5,1500000)-1250000)*25%+MAX(0,F5-1500000)*30%,IF(B5="2023-24",MAX(0,MIN(F5,600000)-300000)*5%+MAX(0,MIN(F5,900000)-600000)*10%+MAX(0,MIN(F5,1200000)-900000)*15%+MAX(0,MIN(F5,1500000)-1200000)*20%+MAX(0,F5-1500000)*30%,IF(B5="2024-25",MAX(0,MIN(F5,700000)-300000)*5%+MAX(0,MIN(F5,1000000)-700000)*10%+MAX(0,MIN(F5,1200000)-1000000)*15%+MAX(0,MIN(F5,1500000)-1200000)*20%+MAX(0,F5-1500000)*30%,IF(B5="2025-26",MAX(0,MIN(F5,800000)-400000)*5%+MAX(0,MIN(F5,1200000)-800000)*10%+MAX(0,MIN(F5,1600000)-1200000)*15%+MAX(0,MIN(F5,2000000)-1600000)*20%+MAX(0,MIN(F5,2400000)-2000000)*25%+MAX(0,F5-2400000)*30%,0))))),2) -> 0 | M5: =ROUND(MAX(IF(C5="OLD",IF(F5<=IF(OR(B5="2014-15",B5="2015-16",B5="2016-17"),500000,IF(OR(B5="2017-18",B5="2018-19"),350000,500000)),MIN(L5,IF(OR(B5="2014-15",B5="2015-16"),2000,IF(B5="2016-17",5000,IF(OR(B5="2017-18",B5="2018-19"),2500,12500)))),0),IF(F5<=IF(OR(B5="2023-24",B5="2024-25"),700000,IF(B5="2025-26",1200000,500000)),MIN(L5,IF(OR(B5="2023-24",B5="2024-25"),25000,IF(B5="2025-26",60000,12500))),0)),IF(AND(C5="NEW",B5="2025-26",F5>1200000),MAX(0,L5-(F5-1200000)),0)),2) -> 0 | N5: =ROUND(IF(C5="OLD",IF(OR(B5="2014-15",B5="2016-17"),IF(F5<=10000000,0,MIN((L5-M5)*15%,MAX(0,(L5-M5)*0%+(F5-10000000)*(70%-30%*0%)))),IF(B5="2015-16",IF(F5<=10000000,0,MIN((L5-M5)*12%,MAX(0,(L5-M5)*0%+(F5-10000000)*(70%-30%*0%)))),IF(OR(B5="2017-18",B5="2018-19"),IF(F5<=5000000,0,IF(F5<=10000000,MIN((L5-M5)*10%,MAX(0,(L5-M5)*0%+(F5-5000000)*(70%-30%*0%))),MIN((L5-M5)*15%,MAX(0,(L5-M5)*10%+(F5-10000000)*(70%-30%*10%))))),IF(F5<=5000000,0,IF(F5<=10000000,MIN((L5-M5)*10%,MAX(0,(L5-M5)*0%+(F5-5000000)*(70%-30%*0%))),IF(F5<=20000000,MIN((L5-M5)*15%,MAX(0,(L5-M5)*10%+(F5-10000000)*(70%-30%*10%))),IF(F5<=50000000,MIN((L5-M5)*25%,MAX(0,(L5-M5)*15%+(F5-20000000)*(70%-30%*15%))),MIN((L5-M5)*37%,MAX(0,(L5-M5)*25%+(F5-50000000)*(70%-30%*25%)))))))))),IF(OR(B5="2023-24",B5="2024-25",B5="2025-26"),IF(F5<=5000000,0,IF(F5<=10000000,MIN((L5-M5)*10%,MAX(0,(L5-M5)*0%+(F5-5000000)*(70%-30%*0%))),IF(F5<=20000000,MIN((L5-M5)*15%,MAX(0,(L5-M5)*10%+(F5-10000000)*(70%-30%*10%))),MIN((L5-M5)*25%,MAX(0,(L5-M5)*15%+(F5-20000000)*(70%-30%*15%)))))),IF(F5<=5000000,0,IF(F5<=10000000,MIN((L5-M5)*10%,MAX(0,(L5-M5)*0%+(F5-5000000)*(70%-30%*0%))),IF(F5<=20000000,MIN((L5-M5)*15%,MAX(0,(L5-M5)*10%+(F5-10000000)*(70%-30%*10%))),IF(F5<=50000000,MIN((L5-M5)*25%,MAX(0,(L5-M5)*15%+(F5-20000000)*(70%-30%*15%))),MIN((L5-M5)*37%,MAX(0,(L5-M5)*25%+(F5-50000000)*(70%-30%*25%))))))))),2) -> 0 | O5: =ROUND((L5-M5+N5)*IF(OR(B5="2014-15",B5="2015-16",B5="2016-17",B5="2017-18"),3%,4%),2) -> 0 | P5: =ROUND(L5-M5+N5+O5,2) -> 0 | Q5: =ROUND(P5-K5,2) -> 0
A6: =6 -> 6 | B6: =Source_Data!A6 -> 2016-17 | C6: =Source_Data!E6 -> OLD | D6: =Source_Data!F6 -> Resident-Senior Citizen | E6: =Source_Data!B6 -> 0 | F6: =Source_Data!D6 -> 0 | G6: =ROUND(IF(C6="OLD",MAX(0,MIN(E6,500000)-IF(D6="Resident-Senior Citizen",300000,250000))*IF(B6="2016-17",10%,5%)+MAX(0,MIN(E6,1000000)-500000)*20%+MAX(0,E6-1000000)*30%,IF(OR(B6="2020-21",B6="2021-22",B6="2022-23"),MAX(0,MIN(E6,500000)-250000)*5%+MAX(0,MIN(E6,750000)-500000)*10%+MAX(0,MIN(E6,1000000)-750000)*15%+MAX(0,MIN(E6,1250000)-1000000)*20%+MAX(0,MIN(E6,1500000)-1250000)*25%+MAX(0,E6-1500000)*30%,IF(B6="2023-24",MAX(0,MIN(E6,600000)-300000)*5%+MAX(0,MIN(E6,900000)-600000)*10%+MAX(0,MIN(E6,1200000)-900000)*15%+MAX(0,MIN(E6,1500000)-1200000)*20%+MAX(0,E6-1500000)*30%,IF(B6="2024-25",MAX(0,MIN(E6,700000)-300000)*5%+MAX(0,MIN(E6,1000000)-700000)*10%+MAX(0,MIN(E6,1200000)-1000000)*15%+MAX(0,MIN(E6,1500000)-1200000)*20%+MAX(0,E6-1500000)*30%,IF(B6="2025-26",MAX(0,MIN(E6,800000)-400000)*5%+MAX(0,MIN(E6,1200000)-800000)*10%+MAX(0,MIN(E6,1600000)-1200000)*15%+MAX(0,MIN(E6,2000000)-1600000)*20%+MAX(0,MIN(E6,2400000)-2000000)*25%+MAX(0,E6-2400000)*30%,0))))),2) -> 0 | H6: =ROUND(MAX(IF(C6="OLD",IF(E6<=IF(OR(B6="2014-15",B6="2015-16",B6="2016-17"),500000,IF(OR(B6="2017-18",B6="2018-19"),350000,500000)),MIN(G6,IF(OR(B6="2014-15",B6="2015-16"),2000,IF(B6="2016-17",5000,IF(OR(B6="2017-18",B6="2018-19"),2500,12500)))),0),IF(E6<=IF(OR(B6="2023-24",B6="2024-25"),700000,IF(B6="2025-26",1200000,500000)),MIN(G6,IF(OR(B6="2023-24",B6="2024-25"),25000,IF(B6="2025-26",60000,12500))),0)),IF(AND(C6="NEW",B6="2025-26",E6>1200000),MAX(0,G6-(E6-1200000)),0)),2) -> 0 | I6: =ROUND(IF(C6="OLD",IF(OR(B6="2014-15",B6="2016-17"),IF(E6<=10000000,0,MIN((G6-H6)*15%,MAX(0,(G6-H6)*0%+(E6-10000000)*(70%-30%*0%)))),IF(B6="2015-16",IF(E6<=10000000,0,MIN((G6-H6)*12%,MAX(0,(G6-H6)*0%+(E6-10000000)*(70%-30%*0%)))),IF(OR(B6="2017-18",B6="2018-19"),IF(E6<=5000000,0,IF(E6<=10000000,MIN((G6-H6)*10%,MAX(0,(G6-H6)*0%+(E6-5000000)*(70%-30%*0%))),MIN((G6-H6)*15%,MAX(0,(G6-H6)*10%+(E6-10000000)*(70%-30%*10%))))),IF(E6<=5000000,0,IF(E6<=10000000,MIN((G6-H6)*10%,MAX(0,(G6-H6)*0%+(E6-5000000)*(70%-30%*0%))),IF(E6<=20000000,MIN((G6-H6)*15%,MAX(0,(G6-H6)*10%+(E6-10000000)*(70%-30%*10%))),IF(E6<=50000000,MIN((G6-H6)*25%,MAX(0,(G6-H6)*15%+(E6-20000000)*(70%-30%*15%))),MIN((G6-H6)*37%,MAX(0,(G6-H6)*25%+(E6-50000000)*(70%-30%*25%)))))))))),IF(OR(B6="2023-24",B6="2024-25",B6="2025-26"),IF(E6<=5000000,0,IF(E6<=10000000,MIN((G6-H6)*10%,MAX(0,(G6-H6)*0%+(E6-5000000)*(70%-30%*0%))),IF(E6<=20000000,MIN((G6-H6)*15%,MAX(0,(G6-H6)*10%+(E6-10000000)*(70%-30%*10%))),MIN((G6-H6)*25%,MAX(0,(G6-H6)*15%+(E6-20000000)*(70%-30%*15%)))))),IF(E6<=5000000,0,IF(E6<=10000000,MIN((G6-H6)*10%,MAX(0,(G6-H6)*0%+(E6-5000000)*(70%-30%*0%))),IF(E6<=20000000,MIN((G6-H6)*15%,MAX(0,(G6-H6)*10%+(E6-10000000)*(70%-30%*10%))),IF(E6<=50000000,MIN((G6-H6)*25%,MAX(0,(G6-H6)*15%+(E6-20000000)*(70%-30%*15%))),MIN((G6-H6)*37%,MAX(0,(G6-H6)*25%+(E6-50000000)*(70%-30%*25%))))))))),2) -> 0 | J6: =ROUND((G6-H6+I6)*IF(OR(B6="2014-15",B6="2015-16",B6="2016-17",B6="2017-18"),3%,4%),2) -> 0 | K6: =ROUND(G6-H6+I6+J6,2) -> 0 | L6: =ROUND(IF(C6="OLD",MAX(0,MIN(F6,500000)-IF(D6="Resident-Senior Citizen",300000,250000))*IF(B6="2016-17",10%,5%)+MAX(0,MIN(F6,1000000)-500000)*20%+MAX(0,F6-1000000)*30%,IF(OR(B6="2020-21",B6="2021-22",B6="2022-23"),MAX(0,MIN(F6,500000)-250000)*5%+MAX(0,MIN(F6,750000)-500000)*10%+MAX(0,MIN(F6,1000000)-750000)*15%+MAX(0,MIN(F6,1250000)-1000000)*20%+MAX(0,MIN(F6,1500000)-1250000)*25%+MAX(0,F6-1500000)*30%,IF(B6="2023-24",MAX(0,MIN(F6,600000)-300000)*5%+MAX(0,MIN(F6,900000)-600000)*10%+MAX(0,MIN(F6,1200000)-900000)*15%+MAX(0,MIN(F6,1500000)-1200000)*20%+MAX(0,F6-1500000)*30%,IF(B6="2024-25",MAX(0,MIN(F6,700000)-300000)*5%+MAX(0,MIN(F6,1000000)-700000)*10%+MAX(0,MIN(F6,1200000)-1000000)*15%+MAX(0,MIN(F6,1500000)-1200000)*20%+MAX(0,F6-1500000)*30%,IF(B6="2025-26",MAX(0,MIN(F6,800000)-400000)*5%+MAX(0,MIN(F6,1200000)-800000)*10%+MAX(0,MIN(F6,1600000)-1200000)*15%+MAX(0,MIN(F6,2000000)-1600000)*20%+MAX(0,MIN(F6,2400000)-2000000)*25%+MAX(0,F6-2400000)*30%,0))))),2) -> 0 | M6: =ROUND(MAX(IF(C6="OLD",IF(F6<=IF(OR(B6="2014-15",B6="2015-16",B6="2016-17"),500000,IF(OR(B6="2017-18",B6="2018-19"),350000,500000)),MIN(L6,IF(OR(B6="2014-15",B6="2015-16"),2000,IF(B6="2016-17",5000,IF(OR(B6="2017-18",B6="2018-19"),2500,12500)))),0),IF(F6<=IF(OR(B6="2023-24",B6="2024-25"),700000,IF(B6="2025-26",1200000,500000)),MIN(L6,IF(OR(B6="2023-24",B6="2024-25"),25000,IF(B6="2025-26",60000,12500))),0)),IF(AND(C6="NEW",B6="2025-26",F6>1200000),MAX(0,L6-(F6-1200000)),0)),2) -> 0 | N6: =ROUND(IF(C6="OLD",IF(OR(B6="2014-15",B6="2016-17"),IF(F6<=10000000,0,MIN((L6-M6)*15%,MAX(0,(L6-M6)*0%+(F6-10000000)*(70%-30%*0%)))),IF(B6="2015-16",IF(F6<=10000000,0,MIN((L6-M6)*12%,MAX(0,(L6-M6)*0%+(F6-10000000)*(70%-30%*0%)))),IF(OR(B6="2017-18",B6="2018-19"),IF(F6<=5000000,0,IF(F6<=10000000,MIN((L6-M6)*10%,MAX(0,(L6-M6)*0%+(F6-5000000)*(70%-30%*0%))),MIN((L6-M6)*15%,MAX(0,(L6-M6)*10%+(F6-10000000)*(70%-30%*10%))))),IF(F6<=5000000,0,IF(F6<=10000000,MIN((L6-M6)*10%,MAX(0,(L6-M6)*0%+(F6-5000000)*(70%-30%*0%))),IF(F6<=20000000,MIN((L6-M6)*15%,MAX(0,(L6-M6)*10%+(F6-10000000)*(70%-30%*10%))),IF(F6<=50000000,MIN((L6-M6)*25%,MAX(0,(L6-M6)*15%+(F6-20000000)*(70%-30%*15%))),MIN((L6-M6)*37%,MAX(0,(L6-M6)*25%+(F6-50000000)*(70%-30%*25%)))))))))),IF(OR(B6="2023-24",B6="2024-25",B6="2025-26"),IF(F6<=5000000,0,IF(F6<=10000000,MIN((L6-M6)*10%,MAX(0,(L6-M6)*0%+(F6-5000000)*(70%-30%*0%))),IF(F6<=20000000,MIN((L6-M6)*15%,MAX(0,(L6-M6)*10%+(F6-10000000)*(70%-30%*10%))),MIN((L6-M6)*25%,MAX(0,(L6-M6)*15%+(F6-20000000)*(70%-30%*15%)))))),IF(F6<=5000000,0,IF(F6<=10000000,MIN((L6-M6)*10%,MAX(0,(L6-M6)*0%+(F6-5000000)*(70%-30%*0%))),IF(F6<=20000000,MIN((L6-M6)*15%,MAX(0,(L6-M6)*10%+(F6-10000000)*(70%-30%*10%))),IF(F6<=50000000,MIN((L6-M6)*25%,MAX(0,(L6-M6)*15%+(F6-20000000)*(70%-30%*15%))),MIN((L6-M6)*37%,MAX(0,(L6-M6)*25%+(F6-50000000)*(70%-30%*25%))))))))),2) -> 0 | O6: =ROUND((L6-M6+N6)*IF(OR(B6="2014-15",B6="2015-16",B6="2016-17",B6="2017-18"),3%,4%),2) -> 0 | P6: =ROUND(L6-M6+N6+O6,2) -> 0 | Q6: =ROUND(P6-K6,2) -> 0
A7: =7 -> 7 | B7: =Source_Data!A7 -> 2017-18 | C7: =Source_Data!E7 -> OLD | D7: =Source_Data!F7 -> Resident-Senior Citizen | E7: =Source_Data!B7 -> 0 | F7: =Source_Data!D7 -> 0 | G7: =ROUND(IF(C7="OLD",MAX(0,MIN(E7,500000)-IF(D7="Resident-Senior Citizen",300000,250000))*IF(B7="2016-17",10%,5%)+MAX(0,MIN(E7,1000000)-500000)*20%+MAX(0,E7-1000000)*30%,IF(OR(B7="2020-21",B7="2021-22",B7="2022-23"),MAX(0,MIN(E7,500000)-250000)*5%+MAX(0,MIN(E7,750000)-500000)*10%+MAX(0,MIN(E7,1000000)-750000)*15%+MAX(0,MIN(E7,1250000)-1000000)*20%+MAX(0,MIN(E7,1500000)-1250000)*25%+MAX(0,E7-1500000)*30%,IF(B7="2023-24",MAX(0,MIN(E7,600000)-300000)*5%+MAX(0,MIN(E7,900000)-600000)*10%+MAX(0,MIN(E7,1200000)-900000)*15%+MAX(0,MIN(E7,1500000)-1200000)*20%+MAX(0,E7-1500000)*30%,IF(B7="2024-25",MAX(0,MIN(E7,700000)-300000)*5%+MAX(0,MIN(E7,1000000)-700000)*10%+MAX(0,MIN(E7,1200000)-1000000)*15%+MAX(0,MIN(E7,1500000)-1200000)*20%+MAX(0,E7-1500000)*30%,IF(B7="2025-26",MAX(0,MIN(E7,800000)-400000)*5%+MAX(0,MIN(E7,1200000)-800000)*10%+MAX(0,MIN(E7,1600000)-1200000)*15%+MAX(0,MIN(E7,2000000)-1600000)*20%+MAX(0,MIN(E7,2400000)-2000000)*25%+MAX(0,E7-2400000)*30%,0))))),2) -> 0 | H7: =ROUND(MAX(IF(C7="OLD",IF(E7<=IF(OR(B7="2014-15",B7="2015-16",B7="2016-17"),500000,IF(OR(B7="2017-18",B7="2018-19"),350000,500000)),MIN(G7,IF(OR(B7="2014-15",B7="2015-16"),2000,IF(B7="2016-17",5000,IF(OR(B7="2017-18",B7="2018-19"),2500,12500)))),0),IF(E7<=IF(OR(B7="2023-24",B7="2024-25"),700000,IF(B7="2025-26",1200000,500000)),MIN(G7,IF(OR(B7="2023-24",B7="2024-25"),25000,IF(B7="2025-26",60000,12500))),0)),IF(AND(C7="NEW",B7="2025-26",E7>1200000),MAX(0,G7-(E7-1200000)),0)),2) -> 0 | I7: =ROUND(IF(C7="OLD",IF(OR(B7="2014-15",B7="2016-17"),IF(E7<=10000000,0,MIN((G7-H7)*15%,MAX(0,(G7-H7)*0%+(E7-10000000)*(70%-30%*0%)))),IF(B7="2015-16",IF(E7<=10000000,0,MIN((G7-H7)*12%,MAX(0,(G7-H7)*0%+(E7-10000000)*(70%-30%*0%)))),IF(OR(B7="2017-18",B7="2018-19"),IF(E7<=5000000,0,IF(E7<=10000000,MIN((G7-H7)*10%,MAX(0,(G7-H7)*0%+(E7-5000000)*(70%-30%*0%))),MIN((G7-H7)*15%,MAX(0,(G7-H7)*10%+(E7-10000000)*(70%-30%*10%))))),IF(E7<=5000000,0,IF(E7<=10000000,MIN((G7-H7)*10%,MAX(0,(G7-H7)*0%+(E7-5000000)*(70%-30%*0%))),IF(E7<=20000000,MIN((G7-H7)*15%,MAX(0,(G7-H7)*10%+(E7-10000000)*(70%-30%*10%))),IF(E7<=50000000,MIN((G7-H7)*25%,MAX(0,(G7-H7)*15%+(E7-20000000)*(70%-30%*15%))),MIN((G7-H7)*37%,MAX(0,(G7-H7)*25%+(E7-50000000)*(70%-30%*25%)))))))))),IF(OR(B7="2023-24",B7="2024-25",B7="2025-26"),IF(E7<=5000000,0,IF(E7<=10000000,MIN((G7-H7)*10%,MAX(0,(G7-H7)*0%+(E7-5000000)*(70%-30%*0%))),IF(E7<=20000000,MIN((G7-H7)*15%,MAX(0,(G7-H7)*10%+(E7-10000000)*(70%-30%*10%))),MIN((G7-H7)*25%,MAX(0,(G7-H7)*15%+(E7-20000000)*(70%-30%*15%)))))),IF(E7<=5000000,0,IF(E7<=10000000,MIN((G7-H7)*10%,MAX(0,(G7-H7)*0%+(E7-5000000)*(70%-30%*0%))),IF(E7<=20000000,MIN((G7-H7)*15%,MAX(0,(G7-H7)*10%+(E7-10000000)*(70%-30%*10%))),IF(E7<=50000000,MIN((G7-H7)*25%,MAX(0,(G7-H7)*15%+(E7-20000000)*(70%-30%*15%))),MIN((G7-H7)*37%,MAX(0,(G7-H7)*25%+(E7-50000000)*(70%-30%*25%))))))))),2) -> 0 | J7: =ROUND((G7-H7+I7)*IF(OR(B7="2014-15",B7="2015-16",B7="2016-17",B7="2017-18"),3%,4%),2) -> 0 | K7: =ROUND(G7-H7+I7+J7,2) -> 0 | L7: =ROUND(IF(C7="OLD",MAX(0,MIN(F7,500000)-IF(D7="Resident-Senior Citizen",300000,250000))*IF(B7="2016-17",10%,5%)+MAX(0,MIN(F7,1000000)-500000)*20%+MAX(0,F7-1000000)*30%,IF(OR(B7="2020-21",B7="2021-22",B7="2022-23"),MAX(0,MIN(F7,500000)-250000)*5%+MAX(0,MIN(F7,750000)-500000)*10%+MAX(0,MIN(F7,1000000)-750000)*15%+MAX(0,MIN(F7,1250000)-1000000)*20%+MAX(0,MIN(F7,1500000)-1250000)*25%+MAX(0,F7-1500000)*30%,IF(B7="2023-24",MAX(0,MIN(F7,600000)-300000)*5%+MAX(0,MIN(F7,900000)-600000)*10%+MAX(0,MIN(F7,1200000)-900000)*15%+MAX(0,MIN(F7,1500000)-1200000)*20%+MAX(0,F7-1500000)*30%,IF(B7="2024-25",MAX(0,MIN(F7,700000)-300000)*5%+MAX(0,MIN(F7,1000000)-700000)*10%+MAX(0,MIN(F7,1200000)-1000000)*15%+MAX(0,MIN(F7,1500000)-1200000)*20%+MAX(0,F7-1500000)*30%,IF(B7="2025-26",MAX(0,MIN(F7,800000)-400000)*5%+MAX(0,MIN(F7,1200000)-800000)*10%+MAX(0,MIN(F7,1600000)-1200000)*15%+MAX(0,MIN(F7,2000000)-1600000)*20%+MAX(0,MIN(F7,2400000)-2000000)*25%+MAX(0,F7-2400000)*30%,0))))),2) -> 0 | M7: =ROUND(MAX(IF(C7="OLD",IF(F7<=IF(OR(B7="2014-15",B7="2015-16",B7="2016-17"),500000,IF(OR(B7="2017-18",B7="2018-19"),350000,500000)),MIN(L7,IF(OR(B7="2014-15",B7="2015-16"),2000,IF(B7="2016-17",5000,IF(OR(B7="2017-18",B7="2018-19"),2500,12500)))),0),IF(F7<=IF(OR(B7="2023-24",B7="2024-25"),700000,IF(B7="2025-26",1200000,500000)),MIN(L7,IF(OR(B7="2023-24",B7="2024-25"),25000,IF(B7="2025-26",60000,12500))),0)),IF(AND(C7="NEW",B7="2025-26",F7>1200000),MAX(0,L7-(F7-1200000)),0)),2) -> 0 | N7: =ROUND(IF(C7="OLD",IF(OR(B7="2014-15",B7="2016-17"),IF(F7<=10000000,0,MIN((L7-M7)*15%,MAX(0,(L7-M7)*0%+(F7-10000000)*(70%-30%*0%)))),IF(B7="2015-16",IF(F7<=10000000,0,MIN((L7-M7)*12%,MAX(0,(L7-M7)*0%+(F7-10000000)*(70%-30%*0%)))),IF(OR(B7="2017-18",B7="2018-19"),IF(F7<=5000000,0,IF(F7<=10000000,MIN((L7-M7)*10%,MAX(0,(L7-M7)*0%+(F7-5000000)*(70%-30%*0%))),MIN((L7-M7)*15%,MAX(0,(L7-M7)*10%+(F7-10000000)*(70%-30%*10%))))),IF(F7<=5000000,0,IF(F7<=10000000,MIN((L7-M7)*10%,MAX(0,(L7-M7)*0%+(F7-5000000)*(70%-30%*0%))),IF(F7<=20000000,MIN((L7-M7)*15%,MAX(0,(L7-M7)*10%+(F7-10000000)*(70%-30%*10%))),IF(F7<=50000000,MIN((L7-M7)*25%,MAX(0,(L7-M7)*15%+(F7-20000000)*(70%-30%*15%))),MIN((L7-M7)*37%,MAX(0,(L7-M7)*25%+(F7-50000000)*(70%-30%*25%)))))))))),IF(OR(B7="2023-24",B7="2024-25",B7="2025-26"),IF(F7<=5000000,0,IF(F7<=10000000,MIN((L7-M7)*10%,MAX(0,(L7-M7)*0%+(F7-5000000)*(70%-30%*0%))),IF(F7<=20000000,MIN((L7-M7)*15%,MAX(0,(L7-M7)*10%+(F7-10000000)*(70%-30%*10%))),MIN((L7-M7)*25%,MAX(0,(L7-M7)*15%+(F7-20000000)*(70%-30%*15%)))))),IF(F7<=5000000,0,IF(F7<=10000000,MIN((L7-M7)*10%,MAX(0,(L7-M7)*0%+(F7-5000000)*(70%-30%*0%))),IF(F7<=20000000,MIN((L7-M7)*15%,MAX(0,(L7-M7)*10%+(F7-10000000)*(70%-30%*10%))),IF(F7<=50000000,MIN((L7-M7)*25%,MAX(0,(L7-M7)*15%+(F7-20000000)*(70%-30%*15%))),MIN((L7-M7)*37%,MAX(0,(L7-M7)*25%+(F7-50000000)*(70%-30%*25%))))))))),2) -> 0 | O7: =ROUND((L7-M7+N7)*IF(OR(B7="2014-15",B7="2015-16",B7="2016-17",B7="2017-18"),3%,4%),2) -> 0 | P7: =ROUND(L7-M7+N7+O7,2) -> 0 | Q7: =ROUND(P7-K7,2) -> 0
A8: =8 -> 8 | B8: =Source_Data!A8 -> 2018-19 | C8: =Source_Data!E8 -> OLD | D8: =Source_Data!F8 -> Resident-Normal Citizen | E8: =Source_Data!B8 -> 0 | F8: =Source_Data!D8 -> 0 | G8: =ROUND(IF(C8="OLD",MAX(0,MIN(E8,500000)-IF(D8="Resident-Senior Citizen",300000,250000))*IF(B8="2016-17",10%,5%)+MAX(0,MIN(E8,1000000)-500000)*20%+MAX(0,E8-1000000)*30%,IF(OR(B8="2020-21",B8="2021-22",B8="2022-23"),MAX(0,MIN(E8,500000)-250000)*5%+MAX(0,MIN(E8,750000)-500000)*10%+MAX(0,MIN(E8,1000000)-750000)*15%+MAX(0,MIN(E8,1250000)-1000000)*20%+MAX(0,MIN(E8,1500000)-1250000)*25%+MAX(0,E8-1500000)*30%,IF(B8="2023-24",MAX(0,MIN(E8,600000)-300000)*5%+MAX(0,MIN(E8,900000)-600000)*10%+MAX(0,MIN(E8,1200000)-900000)*15%+MAX(0,MIN(E8,1500000)-1200000)*20%+MAX(0,E8-1500000)*30%,IF(B8="2024-25",MAX(0,MIN(E8,700000)-300000)*5%+MAX(0,MIN(E8,1000000)-700000)*10%+MAX(0,MIN(E8,1200000)-1000000)*15%+MAX(0,MIN(E8,1500000)-1200000)*20%+MAX(0,E8-1500000)*30%,IF(B8="2025-26",MAX(0,MIN(E8,800000)-400000)*5%+MAX(0,MIN(E8,1200000)-800000)*10%+MAX(0,MIN(E8,1600000)-1200000)*15%+MAX(0,MIN(E8,2000000)-1600000)*20%+MAX(0,MIN(E8,2400000)-2000000)*25%+MAX(0,E8-2400000)*30%,0))))),2) -> 0 | H8: =ROUND(MAX(IF(C8="OLD",IF(E8<=IF(OR(B8="2014-15",B8="2015-16",B8="2016-17"),500000,IF(OR(B8="2017-18",B8="2018-19"),350000,500000)),MIN(G8,IF(OR(B8="2014-15",B8="2015-16"),2000,IF(B8="2016-17",5000,IF(OR(B8="2017-18",B8="2018-19"),2500,12500)))),0),IF(E8<=IF(OR(B8="2023-24",B8="2024-25"),700000,IF(B8="2025-26",1200000,500000)),MIN(G8,IF(OR(B8="2023-24",B8="2024-25"),25000,IF(B8="2025-26",60000,12500))),0)),IF(AND(C8="NEW",B8="2025-26",E8>1200000),MAX(0,G8-(E8-1200000)),0)),2) -> 0 | I8: =ROUND(IF(C8="OLD",IF(OR(B8="2014-15",B8="2016-17"),IF(E8<=10000000,0,MIN((G8-H8)*15%,MAX(0,(G8-H8)*0%+(E8-10000000)*(70%-30%*0%)))),IF(B8="2015-16",IF(E8<=10000000,0,MIN((G8-H8)*12%,MAX(0,(G8-H8)*0%+(E8-10000000)*(70%-30%*0%)))),IF(OR(B8="2017-18",B8="2018-19"),IF(E8<=5000000,0,IF(E8<=10000000,MIN((G8-H8)*10%,MAX(0,(G8-H8)*0%+(E8-5000000)*(70%-30%*0%))),MIN((G8-H8)*15%,MAX(0,(G8-H8)*10%+(E8-10000000)*(70%-30%*10%))))),IF(E8<=5000000,0,IF(E8<=10000000,MIN((G8-H8)*10%,MAX(0,(G8-H8)*0%+(E8-5000000)*(70%-30%*0%))),IF(E8<=20000000,MIN((G8-H8)*15%,MAX(0,(G8-H8)*10%+(E8-10000000)*(70%-30%*10%))),IF(E8<=50000000,MIN((G8-H8)*25%,MAX(0,(G8-H8)*15%+(E8-20000000)*(70%-30%*15%))),MIN((G8-H8)*37%,MAX(0,(G8-H8)*25%+(E8-50000000)*(70%-30%*25%)))))))))),IF(OR(B8="2023-24",B8="2024-25",B8="2025-26"),IF(E8<=5000000,0,IF(E8<=10000000,MIN((G8-H8)*10%,MAX(0,(G8-H8)*0%+(E8-5000000)*(70%-30%*0%))),IF(E8<=20000000,MIN((G8-H8)*15%,MAX(0,(G8-H8)*10%+(E8-10000000)*(70%-30%*10%))),MIN((G8-H8)*25%,MAX(0,(G8-H8)*15%+(E8-20000000)*(70%-30%*15%)))))),IF(E8<=5000000,0,IF(E8<=10000000,MIN((G8-H8)*10%,MAX(0,(G8-H8)*0%+(E8-5000000)*(70%-30%*0%))),IF(E8<=20000000,MIN((G8-H8)*15%,MAX(0,(G8-H8)*10%+(E8-10000000)*(70%-30%*10%))),IF(E8<=50000000,MIN((G8-H8)*25%,MAX(0,(G8-H8)*15%+(E8-20000000)*(70%-30%*15%))),MIN((G8-H8)*37%,MAX(0,(G8-H8)*25%+(E8-50000000)*(70%-30%*25%))))))))),2) -> 0 | J8: =ROUND((G8-H8+I8)*IF(OR(B8="2014-15",B8="2015-16",B8="2016-17",B8="2017-18"),3%,4%),2) -> 0 | K8: =ROUND(G8-H8+I8+J8,2) -> 0 | L8: =ROUND(IF(C8="OLD",MAX(0,MIN(F8,500000)-IF(D8="Resident-Senior Citizen",300000,250000))*IF(B8="2016-17",10%,5%)+MAX(0,MIN(F8,1000000)-500000)*20%+MAX(0,F8-1000000)*30%,IF(OR(B8="2020-21",B8="2021-22",B8="2022-23"),MAX(0,MIN(F8,500000)-250000)*5%+MAX(0,MIN(F8,750000)-500000)*10%+MAX(0,MIN(F8,1000000)-750000)*15%+MAX(0,MIN(F8,1250000)-1000000)*20%+MAX(0,MIN(F8,1500000)-1250000)*25%+MAX(0,F8-1500000)*30%,IF(B8="2023-24",MAX(0,MIN(F8,600000)-300000)*5%+MAX(0,MIN(F8,900000)-600000)*10%+MAX(0,MIN(F8,1200000)-900000)*15%+MAX(0,MIN(F8,1500000)-1200000)*20%+MAX(0,F8-1500000)*30%,IF(B8="2024-25",MAX(0,MIN(F8,700000)-300000)*5%+MAX(0,MIN(F8,1000000)-700000)*10%+MAX(0,MIN(F8,1200000)-1000000)*15%+MAX(0,MIN(F8,1500000)-1200000)*20%+MAX(0,F8-1500000)*30%,IF(B8="2025-26",MAX(0,MIN(F8,800000)-400000)*5%+MAX(0,MIN(F8,1200000)-800000)*10%+MAX(0,MIN(F8,1600000)-1200000)*15%+MAX(0,MIN(F8,2000000)-1600000)*20%+MAX(0,MIN(F8,2400000)-2000000)*25%+MAX(0,F8-2400000)*30%,0))))),2) -> 0 | M8: =ROUND(MAX(IF(C8="OLD",IF(F8<=IF(OR(B8="2014-15",B8="2015-16",B8="2016-17"),500000,IF(OR(B8="2017-18",B8="2018-19"),350000,500000)),MIN(L8,IF(OR(B8="2014-15",B8="2015-16"),2000,IF(B8="2016-17",5000,IF(OR(B8="2017-18",B8="2018-19"),2500,12500)))),0),IF(F8<=IF(OR(B8="2023-24",B8="2024-25"),700000,IF(B8="2025-26",1200000,500000)),MIN(L8,IF(OR(B8="2023-24",B8="2024-25"),25000,IF(B8="2025-26",60000,12500))),0)),IF(AND(C8="NEW",B8="2025-26",F8>1200000),MAX(0,L8-(F8-1200000)),0)),2) -> 0 | N8: =ROUND(IF(C8="OLD",IF(OR(B8="2014-15",B8="2016-17"),IF(F8<=10000000,0,MIN((L8-M8)*15%,MAX(0,(L8-M8)*0%+(F8-10000000)*(70%-30%*0%)))),IF(B8="2015-16",IF(F8<=10000000,0,MIN((L8-M8)*12%,MAX(0,(L8-M8)*0%+(F8-10000000)*(70%-30%*0%)))),IF(OR(B8="2017-18",B8="2018-19"),IF(F8<=5000000,0,IF(F8<=10000000,MIN((L8-M8)*10%,MAX(0,(L8-M8)*0%+(F8-5000000)*(70%-30%*0%))),MIN((L8-M8)*15%,MAX(0,(L8-M8)*10%+(F8-10000000)*(70%-30%*10%))))),IF(F8<=5000000,0,IF(F8<=10000000,MIN((L8-M8)*10%,MAX(0,(L8-M8)*0%+(F8-5000000)*(70%-30%*0%))),IF(F8<=20000000,MIN((L8-M8)*15%,MAX(0,(L8-M8)*10%+(F8-10000000)*(70%-30%*10%))),IF(F8<=50000000,MIN((L8-M8)*25%,MAX(0,(L8-M8)*15%+(F8-20000000)*(70%-30%*15%))),MIN((L8-M8)*37%,MAX(0,(L8-M8)*25%+(F8-50000000)*(70%-30%*25%)))))))))),IF(OR(B8="2023-24",B8="2024-25",B8="2025-26"),IF(F8<=5000000,0,IF(F8<=10000000,MIN((L8-M8)*10%,MAX(0,(L8-M8)*0%+(F8-5000000)*(70%-30%*0%))),IF(F8<=20000000,MIN((L8-M8)*15%,MAX(0,(L8-M8)*10%+(F8-10000000)*(70%-30%*10%))),MIN((L8-M8)*25%,MAX(0,(L8-M8)*15%+(F8-20000000)*(70%-30%*15%)))))),IF(F8<=5000000,0,IF(F8<=10000000,MIN((L8-M8)*10%,MAX(0,(L8-M8)*0%+(F8-5000000)*(70%-30%*0%))),IF(F8<=20000000,MIN((L8-M8)*15%,MAX(0,(L8-M8)*10%+(F8-10000000)*(70%-30%*10%))),IF(F8<=50000000,MIN((L8-M8)*25%,MAX(0,(L8-M8)*15%+(F8-20000000)*(70%-30%*15%))),MIN((L8-M8)*37%,MAX(0,(L8-M8)*25%+(F8-50000000)*(70%-30%*25%))))))))),2) -> 0 | O8: =ROUND((L8-M8+N8)*IF(OR(B8="2014-15",B8="2015-16",B8="2016-17",B8="2017-18"),3%,4%),2) -> 0 | P8: =ROUND(L8-M8+N8+O8,2) -> 0 | Q8: =ROUND(P8-K8,2) -> 0
A9: =9 -> 9 | B9: =Source_Data!A9 -> 2019-20 | C9: =Source_Data!E9 -> OLD | D9: =Source_Data!F9 -> Resident-Normal Citizen | E9: =Source_Data!B9 -> 0 | F9: =Source_Data!D9 -> 0 | G9: =ROUND(IF(C9="OLD",MAX(0,MIN(E9,500000)-IF(D9="Resident-Senior Citizen",300000,250000))*IF(B9="2016-17",10%,5%)+MAX(0,MIN(E9,1000000)-500000)*20%+MAX(0,E9-1000000)*30%,IF(OR(B9="2020-21",B9="2021-22",B9="2022-23"),MAX(0,MIN(E9,500000)-250000)*5%+MAX(0,MIN(E9,750000)-500000)*10%+MAX(0,MIN(E9,1000000)-750000)*15%+MAX(0,MIN(E9,1250000)-1000000)*20%+MAX(0,MIN(E9,1500000)-1250000)*25%+MAX(0,E9-1500000)*30%,IF(B9="2023-24",MAX(0,MIN(E9,600000)-300000)*5%+MAX(0,MIN(E9,900000)-600000)*10%+MAX(0,MIN(E9,1200000)-900000)*15%+MAX(0,MIN(E9,1500000)-1200000)*20%+MAX(0,E9-1500000)*30%,IF(B9="2024-25",MAX(0,MIN(E9,700000)-300000)*5%+MAX(0,MIN(E9,1000000)-700000)*10%+MAX(0,MIN(E9,1200000)-1000000)*15%+MAX(0,MIN(E9,1500000)-1200000)*20%+MAX(0,E9-1500000)*30%,IF(B9="2025-26",MAX(0,MIN(E9,800000)-400000)*5%+MAX(0,MIN(E9,1200000)-800000)*10%+MAX(0,MIN(E9,1600000)-1200000)*15%+MAX(0,MIN(E9,2000000)-1600000)*20%+MAX(0,MIN(E9,2400000)-2000000)*25%+MAX(0,E9-2400000)*30%,0))))),2) -> 0 | H9: =ROUND(MAX(IF(C9="OLD",IF(E9<=IF(OR(B9="2014-15",B9="2015-16",B9="2016-17"),500000,IF(OR(B9="2017-18",B9="2018-19"),350000,500000)),MIN(G9,IF(OR(B9="2014-15",B9="2015-16"),2000,IF(B9="2016-17",5000,IF(OR(B9="2017-18",B9="2018-19"),2500,12500)))),0),IF(E9<=IF(OR(B9="2023-24",B9="2024-25"),700000,IF(B9="2025-26",1200000,500000)),MIN(G9,IF(OR(B9="2023-24",B9="2024-25"),25000,IF(B9="2025-26",60000,12500))),0)),IF(AND(C9="NEW",B9="2025-26",E9>1200000),MAX(0,G9-(E9-1200000)),0)),2) -> 0 | I9: =ROUND(IF(C9="OLD",IF(OR(B9="2014-15",B9="2016-17"),IF(E9<=10000000,0,MIN((G9-H9)*15%,MAX(0,(G9-H9)*0%+(E9-10000000)*(70%-30%*0%)))),IF(B9="2015-16",IF(E9<=10000000,0,MIN((G9-H9)*12%,MAX(0,(G9-H9)*0%+(E9-10000000)*(70%-30%*0%)))),IF(OR(B9="2017-18",B9="2018-19"),IF(E9<=5000000,0,IF(E9<=10000000,MIN((G9-H9)*10%,MAX(0,(G9-H9)*0%+(E9-5000000)*(70%-30%*0%))),MIN((G9-H9)*15%,MAX(0,(G9-H9)*10%+(E9-10000000)*(70%-30%*10%))))),IF(E9<=5000000,0,IF(E9<=10000000,MIN((G9-H9)*10%,MAX(0,(G9-H9)*0%+(E9-5000000)*(70%-30%*0%))),IF(E9<=20000000,MIN((G9-H9)*15%,MAX(0,(G9-H9)*10%+(E9-10000000)*(70%-30%*10%))),IF(E9<=50000000,MIN((G9-H9)*25%,MAX(0,(G9-H9)*15%+(E9-20000000)*(70%-30%*15%))),MIN((G9-H9)*37%,MAX(0,(G9-H9)*25%+(E9-50000000)*(70%-30%*25%)))))))))),IF(OR(B9="2023-24",B9="2024-25",B9="2025-26"),IF(E9<=5000000,0,IF(E9<=10000000,MIN((G9-H9)*10%,MAX(0,(G9-H9)*0%+(E9-5000000)*(70%-30%*0%))),IF(E9<=20000000,MIN((G9-H9)*15%,MAX(0,(G9-H9)*10%+(E9-10000000)*(70%-30%*10%))),MIN((G9-H9)*25%,MAX(0,(G9-H9)*15%+(E9-20000000)*(70%-30%*15%)))))),IF(E9<=5000000,0,IF(E9<=10000000,MIN((G9-H9)*10%,MAX(0,(G9-H9)*0%+(E9-5000000)*(70%-30%*0%))),IF(E9<=20000000,MIN((G9-H9)*15%,MAX(0,(G9-H9)*10%+(E9-10000000)*(70%-30%*10%))),IF(E9<=50000000,MIN((G9-H9)*25%,MAX(0,(G9-H9)*15%+(E9-20000000)*(70%-30%*15%))),MIN((G9-H9)*37%,MAX(0,(G9-H9)*25%+(E9-50000000)*(70%-30%*25%))))))))),2) -> 0 | J9: =ROUND((G9-H9+I9)*IF(OR(B9="2014-15",B9="2015-16",B9="2016-17",B9="2017-18"),3%,4%),2) -> 0 | K9: =ROUND(G9-H9+I9+J9,2) -> 0 | L9: =ROUND(IF(C9="OLD",MAX(0,MIN(F9,500000)-IF(D9="Resident-Senior Citizen",300000,250000))*IF(B9="2016-17",10%,5%)+MAX(0,MIN(F9,1000000)-500000)*20%+MAX(0,F9-1000000)*30%,IF(OR(B9="2020-21",B9="2021-22",B9="2022-23"),MAX(0,MIN(F9,500000)-250000)*5%+MAX(0,MIN(F9,750000)-500000)*10%+MAX(0,MIN(F9,1000000)-750000)*15%+MAX(0,MIN(F9,1250000)-1000000)*20%+MAX(0,MIN(F9,1500000)-1250000)*25%+MAX(0,F9-1500000)*30%,IF(B9="2023-24",MAX(0,MIN(F9,600000)-300000)*5%+MAX(0,MIN(F9,900000)-600000)*10%+MAX(0,MIN(F9,1200000)-900000)*15%+MAX(0,MIN(F9,1500000)-1200000)*20%+MAX(0,F9-1500000)*30%,IF(B9="2024-25",MAX(0,MIN(F9,700000)-300000)*5%+MAX(0,MIN(F9,1000000)-700000)*10%+MAX(0,MIN(F9,1200000)-1000000)*15%+MAX(0,MIN(F9,1500000)-1200000)*20%+MAX(0,F9-1500000)*30%,IF(B9="2025-26",MAX(0,MIN(F9,800000)-400000)*5%+MAX(0,MIN(F9,1200000)-800000)*10%+MAX(0,MIN(F9,1600000)-1200000)*15%+MAX(0,MIN(F9,2000000)-1600000)*20%+MAX(0,MIN(F9,2400000)-2000000)*25%+MAX(0,F9-2400000)*30%,0))))),2) -> 0 | M9: =ROUND(MAX(IF(C9="OLD",IF(F9<=IF(OR(B9="2014-15",B9="2015-16",B9="2016-17"),500000,IF(OR(B9="2017-18",B9="2018-19"),350000,500000)),MIN(L9,IF(OR(B9="2014-15",B9="2015-16"),2000,IF(B9="2016-17",5000,IF(OR(B9="2017-18",B9="2018-19"),2500,12500)))),0),IF(F9<=IF(OR(B9="2023-24",B9="2024-25"),700000,IF(B9="2025-26",1200000,500000)),MIN(L9,IF(OR(B9="2023-24",B9="2024-25"),25000,IF(B9="2025-26",60000,12500))),0)),IF(AND(C9="NEW",B9="2025-26",F9>1200000),MAX(0,L9-(F9-1200000)),0)),2) -> 0 | N9: =ROUND(IF(C9="OLD",IF(OR(B9="2014-15",B9="2016-17"),IF(F9<=10000000,0,MIN((L9-M9)*15%,MAX(0,(L9-M9)*0%+(F9-10000000)*(70%-30%*0%)))),IF(B9="2015-16",IF(F9<=10000000,0,MIN((L9-M9)*12%,MAX(0,(L9-M9)*0%+(F9-10000000)*(70%-30%*0%)))),IF(OR(B9="2017-18",B9="2018-19"),IF(F9<=5000000,0,IF(F9<=10000000,MIN((L9-M9)*10%,MAX(0,(L9-M9)*0%+(F9-5000000)*(70%-30%*0%))),MIN((L9-M9)*15%,MAX(0,(L9-M9)*10%+(F9-10000000)*(70%-30%*10%))))),IF(F9<=5000000,0,IF(F9<=10000000,MIN((L9-M9)*10%,MAX(0,(L9-M9)*0%+(F9-5000000)*(70%-30%*0%))),IF(F9<=20000000,MIN((L9-M9)*15%,MAX(0,(L9-M9)*10%+(F9-10000000)*(70%-30%*10%))),IF(F9<=50000000,MIN((L9-M9)*25%,MAX(0,(L9-M9)*15%+(F9-20000000)*(70%-30%*15%))),MIN((L9-M9)*37%,MAX(0,(L9-M9)*25%+(F9-50000000)*(70%-30%*25%)))))))))),IF(OR(B9="2023-24",B9="2024-25",B9="2025-26"),IF(F9<=5000000,0,IF(F9<=10000000,MIN((L9-M9)*10%,MAX(0,(L9-M9)*0%+(F9-5000000)*(70%-30%*0%))),IF(F9<=20000000,MIN((L9-M9)*15%,MAX(0,(L9-M9)*10%+(F9-10000000)*(70%-30%*10%))),MIN((L9-M9)*25%,MAX(0,(L9-M9)*15%+(F9-20000000)*(70%-30%*15%)))))),IF(F9<=5000000,0,IF(F9<=10000000,MIN((L9-M9)*10%,MAX(0,(L9-M9)*0%+(F9-5000000)*(70%-30%*0%))),IF(F9<=20000000,MIN((L9-M9)*15%,MAX(0,(L9-M9)*10%+(F9-10000000)*(70%-30%*10%))),IF(F9<=50000000,MIN((L9-M9)*25%,MAX(0,(L9-M9)*15%+(F9-20000000)*(70%-30%*15%))),MIN((L9-M9)*37%,MAX(0,(L9-M9)*25%+(F9-50000000)*(70%-30%*25%))))))))),2) -> 0 | O9: =ROUND((L9-M9+N9)*IF(OR(B9="2014-15",B9="2015-16",B9="2016-17",B9="2017-18"),3%,4%),2) -> 0 | P9: =ROUND(L9-M9+N9+O9,2) -> 0 | Q9: =ROUND(P9-K9,2) -> 0
